export const catchAsync =
  (fn: Function) => async (req: any, res: any, next: any) => {
    try {
      await fn(req, res, next);
    } catch (error) {
      next(error);
    }
  };
